<?xml version="1.0"?>
<robot name="food_robot" xmlns:xacro="http://wiki.ros.org/xacro">

  <xacro:include filename="$(find food_maker)/urdf/right_arm/right_arm.urdf.xacro"/>
  <xacro:include filename="$(find food_maker)/urdf/left_arm/left_arm.urdf.xacro"/>
  <xacro:include filename="$(find food_maker)/urdf/robot.gazebo"/>
  
 <link name="robot_footprint"></link>
    <joint name="robot_footprint_joint" type="fixed">
        <parent link="robot_footprint" />
        <child link="base_link" />
        <origin
      xyz="0 0 0.0"
      rpy="0 0 3.14159" />
    </joint>
  <link
    name="base_link">
    <inertial>
      <origin
        xyz="-7.1494E-18 -2.7744E-07 0.29426"
        rpy="0 0 0" />
      <mass
        value="50000" />
      <inertia
        ixx="7.4342"
        ixy="-4.7031E-22"
        ixz="-2.9075E-16"
        iyy="7.4342"
        iyz="7.4785E-06"
        izz="6.4972" />
    </inertial>
    <visual>
      <origin
        xyz="0 0 0"
        rpy="0 0 0" />
      <geometry>
        <mesh
          filename="package://food_maker/meshes/base/base_link.STL" />
      </geometry>
      <material
        name="">
        <color
          rgba="0.79216 0.81961 0.93333 1" />
      </material>
    </visual>
    <collision>
      <origin
        xyz="0 0 0"
        rpy="0 0 0" />
      <geometry>
        <mesh
          filename="package://food_maker/meshes/base/base_link.STL" />
      </geometry>
    </collision>
  </link>
  <link
    name="hip_link">
    <inertial>
      <origin
        xyz="0 0 0.26328"
        rpy="0 0 0" />
      <mass
        value="73.153" />
      <inertia
        ixx="2.4336"
        ixy="-7.1738E-06"
        ixz="8.3078E-07"
        iyy="2.3897"
        iyz="5.695E-05"
        izz="1.7295" />
    </inertial>
    <visual>
      <origin
        xyz="0 0 0"
        rpy="0 0 0" />
      <geometry>
        <mesh
          filename="package://food_maker/meshes/base/hip_link.STL" />
      </geometry>
      <material
        name="">
        <color
          rgba="0.79216 0.81961 0.93333 1" />
      </material>
    </visual>
    <collision>
      <origin
        xyz="0 0 0"
        rpy="0 0 0" />
      <geometry>
        <mesh
          filename="package://food_maker/meshes/base/hip_link.STL" />
      </geometry>
    </collision>
  </link>
  <joint
    name="hip_joint"
    type="revolute">
    <origin
      xyz="0 0 0.74594"
      rpy="0 0 3.14159" />
    <parent
      link="base_link" />
    <child
      link="hip_link" />
    <axis
      xyz="0 0 1" />
    <limit
      lower="${-pi}"
      upper="${pi}"
      effort="500"
      velocity="100" />
  </joint>
  <joint
    name="right_shoulder_joint"
    type="fixed">
    <origin
      xyz="0 0.246 0.38513"
      rpy="-1.5708 -1.5708 0" />
    <parent
      link="hip_link" />
    <child
      link="r_shoulder_hinge" />
    <axis
      xyz="0 0 1" />
  </joint>
  <joint
    name="left_shoulder_joint"
    type="fixed">
    <origin
      xyz="0 -0.246 0.38513"
      rpy="1.5708 1.5708 0" />
    <parent
      link="hip_link" />
    <child
      link="l_shoulder_hinge" />
    <axis
      xyz="0 0 -1" />
  </joint>

   <!-- Lidar -->
    <link name="base_laser">
        <inertial>
            <origin xyz="-0.00029774 0.0066667 0.00013047" rpy="0 0 0" />
            <mass value="0.15717" />
            <inertia ixx="6.7885E-05" ixy="-1.3987E-07" ixz="-8.1554E-07" iyy="0.00013173" iyz="-9.0932E-08" izz="7.1972E-05" />
        </inertial>
        <visual>
            <origin xyz="0 0 0" rpy="0 0 0" />
            <geometry>
                <mesh filename="package://food_maker/meshes/ydlidar.dae" />
            </geometry>
            <material name="">
                <color rgba="0.64706 0.61961 0.58824 1" />
            </material>
        </visual>
        <!-- <collision> Is removed to improve gazebo's real time factor
            <origin xyz="0 0 0" rpy="0 0 0" />
            <geometry>
                <mesh filename="package://food_maker/meshes/ydlidar.dae" />
            </geometry>
        </collision> -->
    </link>
    <link name="laser_frame">
        <inertial>
            <origin xyz="-0.00036659 0.00064155 -0.00027052" rpy="0 0 0" />
            <mass value="0.25482" />
            <inertia ixx="8.9194E-05" ixy="1.8116E-07" ixz="3.6435E-08" iyy="0.00018279" iyz="2.423E-07" izz="0.00011103" />
        </inertial>
    </link>
    <joint name="laser_joint" type="fixed">
        <origin xyz="0 0 0.03172" rpy="0 0 0" />
        <parent link="base_laser" />
        <child link="laser_frame" />
        <axis xyz="0 0 0" />
    </joint>
    <joint name="laser_optical_joint" type="fixed">
        <origin xyz="0 0 0.07" rpy="0 0 0" />
        <parent link="base_link" />
        <child link="base_laser" />
        <axis xyz="0 0 0" />
    </joint>

  <joint name="camera_joint" type="fixed">
    <axis xyz="0 1 0" />
    <origin xyz="0 0 1.5" rpy="0 0.3 3.14"/>
    <parent link="base_link"/>
    <child link="camera_link"/>
  </joint>

  <!-- Camera -->
  <link name="camera_link">
    <collision>
      <origin xyz="0 0 0" rpy="0 0 0"/>
      <geometry>
    <box size="0.1 0.1 0.1"/>
      </geometry>
    </collision>

    <visual>
      <origin xyz="0 0 0" rpy="0 0 0"/>
      <geometry>
    <box size="0.1 0.1 0.1"/>
      </geometry>
      <material name="black"/>
    </visual>

    <inertial>
      <mass value="1e-5" />
      <origin xyz="0 0 0" rpy="0 0 0"/>
      <inertia ixx="1e-6" ixy="0" ixz="0" iyy="1e-6" iyz="0" izz="1e-6" />
    </inertial>
  </link>

    <transmission name="hip_trans">
      <type>transmission_interface/SimpleTransmission</type>
      <joint name="hip_joint">
        <hardwareInterface>hardware_interface/EffortJointInterface</hardwareInterface>
      </joint>
      <actuator name="hip_motor">
        <mechanicalReduction>1</mechanicalReduction>
      </actuator>
    </transmission> 

</robot>
